<?xml version="1.0"?>
<robot xmlns:xacro="http://www.ros.org/wiki/xacro"  >

    <xacro:include filename="inertial_macros.xacro"/>

    <material name="white">
        <color rgba="1 1 1 1" />
    </material>

    <material name="orange">
        <color rgba="1 0.3 0.1 1" />
    </material>

    <material name="blue">
        <color rgba="0.2 0.2 1 1" />
    </material>

    <material name="black">
        <color rgba="0 0 0 1" />
    </material>

    <material name="red">
        <color rgba="1 0 0 1" />
    </material>

     <!-- BASE LINK -->
    <link name="base_link">

    </link>

    <!--BASE FOOT-PRINT -->
    <joint name="base_footprint_joint" type="fixed">
        <parent link="base_link"/>
        <child link="base_footprint"/>
        <origin xyz="0 0 0" rpy="0 0 0"/>
    </joint>

    <link name="base_footprint">
    </link>



     <!-- cHASIIS LINK -->
    <joint name="chassis_joint" type="fixed">   
        <parent link="base_link"/>
        <child link="chassis"/>
        <origin xyz="-0.1 0 0"/>

    </joint>
    
    <link name="chassis">
        <visual>
            <origin xyz="0.15 0 0.075"/>
            <geometry>
                <box size="0.14 0.13 0.2"/>
            </geometry>
            <material name="white"/>
        </visual>

        <collision>
            <origin xyz="0.15 0 0.075"/>
            <geometry>
                <box size="0.14 0.13 0.2"/>
            </geometry>
        </collision>

        <xacro:inertial_box mass="0.5" x="0.14"  y="0.13" z="0.2">
                <origin xyz="0.15 0 0.075" rpy="0 0 0"/>

        </xacro:inertial_box>

    </link>

    <gazebo reference="chassis">
        <material>Gazebo/White</material>
    </gazebo>

    <!-- LEFT WHEEL LINK -->

    <joint name="left_wheel_joint" type="continuous">
        <parent link="base_link"/>
        <child link="left_wheel"/>
        <origin xyz="0.075 0.155 0" rpy="-${pi/2} 0 0"/>
        <axis xyz="0 0 1"/>

    </joint>

    <link name="left_wheel">
        <visual>
            <geometry>
                <cylinder radius="0.06" length=".055"/>
            </geometry>
            <material name="blue"/>
        </visual>

        <collision>
            <geometry>
                <sphere radius="0.06"/>
            </geometry>
        </collision>

        <xacro:inertial_cylinder mass="0.1" length="0.055" radius="0.06">
            <origin xyz="0 0 0" rpy="0 0 0"/>
        </xacro:inertial_cylinder>
    </link>

    <gazebo reference="left_wheel">
        <material>Gazebo/Blue</material>
    </gazebo>


    <!-- RIGHT WHEEL LINK -->

    <joint name="right_wheel_joint" type="continuous">
        <parent link="base_link"/>
        <child link="right_wheel"/>
        <origin xyz="0.075 -0.155 0" rpy="${pi/2} 0 0"/>
        <axis xyz="0 0 -1"/>

    </joint>

    <link name="right_wheel">
        <visual>
            <geometry>
                <cylinder radius="0.06" length=".055"/>
            </geometry>
            <material name="blue"/>
        </visual>

        <collision>
            <geometry>
                <sphere radius="0.06"/>
            </geometry>
        </collision>

        <xacro:inertial_cylinder mass="0.1" length="0.055" radius="0.06">
            <origin xyz="0 0 0" rpy="0 0 0"/>
        </xacro:inertial_cylinder>
    </link>

    <gazebo reference="right_wheel">
        <material>Gazebo/Blue</material>
    </gazebo>

    <!-- FRONT CASTER WHEEL -->
    <joint name="caster_wheel_front_joint" type="fixed">
        <parent link="chassis"/>
        <child link="caster_wheel_front"/>
        <origin xyz="0.24 0 0"/>
    </joint>

    <link name="caster_wheel_front">
        <visual>
            <geometry>
                <sphere radius="0.06"/>
            </geometry>
            <material name="black"/>
        </visual>
        <collision>
            <geometry>
                <sphere radius="0.06"/>
            </geometry>
        </collision>
        <xacro:inertial_sphere mass="0.1" radius="0.06">
            <origin xyz="0 0 0" rpy="0 0 0"/>
        </xacro:inertial_sphere>
    </link>

    <gazebo reference="caster_wheel_front">
        <material>Gazebo/Black</material>
        <mu1 value="0.001"/>
        <mu2 value="0.001"/>
    </gazebo>
    
    <!-- REAR CASTER WHEEL -->
    <joint name="caster_wheel_rear_joint" type="fixed">
        <parent link="chassis"/>
        <child link="caster_wheel_rear"/>
        <origin xyz="0.06 0 0"/>
    </joint>

    <link name="caster_wheel_rear">
        <visual>
            <geometry>
                <sphere radius="0.06"/>
            </geometry>
            <material name="black"/>
        </visual>
        <collision>
            <geometry>
                <sphere radius="0.06"/>
            </geometry>
        </collision>
        <xacro:inertial_sphere mass="0.1" radius="0.06">
            <origin xyz="0 0 0" rpy="0 0 0"/>
        </xacro:inertial_sphere>
    </link>

    <gazebo reference="caster_wheel_rear">
        <material>Gazebo/Black</material>
        <mu1 value="0.001"/>
        <mu2 value="0.001"/>
    </gazebo>

</robot>